<mujoco>
    <worldbody>
    <body name="torso" pos="0 0 3">
    <camera name="track" mode="trackcom" pos="0 -3 0.3" xyaxes="1 0 0 0 0 1"/>
    <site name="box_range" type="box" pos="0.4 0 0" size=".05 .05 .05" rgba="0 .9 0 1" euler="0 90 0"/>
    <geom name="torso_geom" pos="0 0 0" size="0.25" type="sphere"/>
    <joint armature="0" damping="0" limited="false" margin="0.01" name="root" pos="0 0 0" type="free"/>
    <body name="front_left_leg" pos="0 0 0">
      <geom fromto="0.0 0.0 0.0 0.2 0.2 0.0" name="aux_1_geom" size="0.08" type="capsule"/>
      <body name="aux_1" pos="0.2 0.2 0">
        <joint axis="0 0 1" name="hip_1" pos="0.0 0.0 0.0" range="-30 30" type="hinge"/>
        <geom fromto="0.0 0.0 0.0 0.2 0.2 0.0" name="left_leg_geom" size="0.08" type="capsule"/>
        <body pos="0.2 0.2 0">
          <joint axis="-1 1 0" name="ankle_1" pos="0.0 0.0 0.0" range="30 70" type="hinge"/>
          <geom fromto="0.0 0.0 0.0 0.4 0.4 0.0" name="left_ankle_geom" size="0.08" type="capsule"/>
        </body>
      </body>
    </body>
    <body name="front_right_leg" pos="0 0 0">
      <geom fromto="0.0 0.0 0.0 -0.2 0.2 0.0" name="aux_2_geom" size="0.08" type="capsule"/>
      <body name="aux_2" pos="-0.2 0.2 0">
        <joint axis="0 0 1" name="hip_2" pos="0.0 0.0 0.0" range="-30 30" type="hinge"/>
        <geom fromto="0.0 0.0 0.0 -0.2 0.2 0.0" name="right_leg_geom" size="0.08" type="capsule"/>
        <body pos="-0.2 0.2 0">
          <joint axis="1 1 0" name="ankle_2" pos="0.0 0.0 0.0" range="-70 -30" type="hinge"/>
          <geom fromto="0.0 0.0 0.0 -0.4 0.4 0.0" name="right_ankle_geom" size="0.08" type="capsule"/>
        </body>
      </body>
    </body>
    <body name="back_leg" pos="0 0 0">
      <geom fromto="0.0 0.0 0.0 -0.2 -0.2 0.0" name="aux_3_geom" size="0.08" type="capsule"/>
      <body name="aux_3" pos="-0.2 -0.2 0">
        <joint axis="0 0 1" name="hip_3" pos="0.0 0.0 0.0" range="-30 30" type="hinge"/>
        <geom fromto="0.0 0.0 0.0 -0.2 -0.2 0.0" name="back_leg_geom" size="0.08" type="capsule"/>
        <body pos="-0.2 -0.2 0">
          <joint axis="-1 1 0" name="ankle_3" pos="0.0 0.0 0.0" range="-70 -30" type="hinge"/>
          <geom fromto="0.0 0.0 0.0 -0.4 -0.4 0.0" name="third_ankle_geom" size="0.08" type="capsule"/>
        </body>
      </body>
    </body>
    <body name="right_back_leg" pos="0 0 0">
      <geom fromto="0.0 0.0 0.0 0.2 -0.2 0.0" name="aux_4_geom" size="0.08" type="capsule"/>
      <body name="aux_4" pos="0.2 -0.2 0">
        <joint axis="0 0 1" name="hip_4" pos="0.0 0.0 0.0" range="-30 30" type="hinge"/>
        <geom fromto="0.0 0.0 0.0 0.2 -0.2 0.0" name="rightback_leg_geom" size="0.08" type="capsule"/>
        <body pos="0.2 -0.2 0">
          <joint axis="1 1 0" name="ankle_4" pos="0.0 0.0 0.0" range="30 70" type="hinge"/>
          <geom fromto="0.0 0.0 0.0 0.4 -0.4 0.0" name="fourth_ankle_geom" size="0.08" type="capsule"/>
        </body>
      </body>
    </body>
    </body>
    <light diffuse=".5 .5 .5" pos="0 0 3" dir="0 0 -1" />
    <geom type="plane" size="15 15 3.330669E-16" rgba=".9 0 0 1" />
    <body pos="0.53 1.471 0.5">
      <geom type="box" size="0.05 1.5 0.5" euler="0 0 0" rgba="0 .9 0 1" />
    </body>
    <body pos="-0.934 -0.053 0.488">
      <geom type="box" size="1.5 0.05 0.5" euler="0 0 0" rgba="0 .9 0 1" />
    </body>
    <body pos="-1.027519 2.838878 0.5085219">
      <geom type="box" size="1.5 0.05 0.5" euler="0 0 0" rgba="0 .9 0 1" />
    </body>
    <body pos="3.927995 -6.745218 0.4348531" name="target_1">
      <geom type="box" size="0.5 0.5 0.5" euler="0 0 0" rgba="255 0 0 1" />
    </body>
    <body pos="-1.864272 6.520146 0.386694" name="target_3">
      <geom type="box" size="0.5 0.5 0.5" euler="0 0 0" rgba="255 0 0 1" />
    </body>
    <body pos="-8.812729 0.1686049 0.4022825">
      <geom type="box" size="2.5 0.05 0.5" euler="0 0 0" rgba="0 .9 0 1" />
    </body>
    <body pos="-5.367813 -6.286523 0.5278883" name="target_2">
      <geom type="box" size="0.5 0.5 0.5" euler="0 0 0" rgba="255 0 0 1" />
    </body>
  </worldbody>
  <actuator>
    <motor ctrllimited="true" ctrlrange="-1.0 1.0" joint="hip_4" gear="150"/>
    <motor ctrllimited="true" ctrlrange="-1.0 1.0" joint="ankle_4" gear="150"/>
    <motor ctrllimited="true" ctrlrange="-1.0 1.0" joint="hip_1" gear="150"/>
    <motor ctrllimited="true" ctrlrange="-1.0 1.0" joint="ankle_1" gear="150"/>
    <motor ctrllimited="true" ctrlrange="-1.0 1.0" joint="hip_2" gear="150"/>
    <motor ctrllimited="true" ctrlrange="-1.0 1.0" joint="ankle_2" gear="150"/>
    <motor ctrllimited="true" ctrlrange="-1.0 1.0" joint="hip_3" gear="150"/>
    <motor ctrllimited="true" ctrlrange="-1.0 1.0" joint="ankle_3" gear="150"/>
  </actuator>

  <sensor>
    <rangefinder name="box1" site="box_range" cutoff="20"/>
    <frameyaxis name="yAxis" objtype="site" objname="box_range"/>
  </sensor>
</mujoco>
